Workbook

Sheet Tabla dinámica 1
I1: UGT | J1: Provincia | K1: Distrito | L1: Institución educativa | M1: COUNTA de Relación con estudiante
I2: VALLE FORTALEZA | J2: BOLOGNESI | K2: ANTONIO RAYMONDI | L2: 451 | M2: 18 | P2: Asistente | Q2: COUNTUNIQUE de Apellidos y nombres
K3: CAJACAY | L3: 048 ELVA BARBA TRINIDAD | M3: 12 | Q3: 0
L4: 1649 | M4: 12 | O4: Total | Q4: 0
L5: 616 | M5: 6 | O5: HUARMEY | P5: Docente | Q5: 9
K6: COLQUIOC | L6: 028 | M6: 5 | P6: Familia | Q6: 48
L7: 030 | M7: 4 | O7: Total HUARMEY | Q7: 56
L8: 1646 | M8: 7 | O8: MINA | P8: Docente | Q8: 22
L9: 357 | M9: 19 | P9: Familia | Q9: 293
J10: RECUAY | K10: PARARIN | L10: 2626 | M10: 4 | O10: Total MINA | Q10: 315
L11: 394 | M11: 3 | O11: SAN MARCOS | P11: Docente | Q11: 8
L12: 416 - Rinconada | M12: 23 | P12: Familia | Q12: 60
I13: Suma total | M13: 113 | O13: Total SAN MARCOS | Q13: 68
O14: VALLE FORTALEZA | P14: Docente | Q14: 38
P15: Familia | Q15: 153
O16: Total VALLE FORTALEZA | Q16: 189
O17: Suma total | Q17: 628
I29: UGT | J29: Provincia | K29: Distrito | L29: Institución educativa | M29: COUNTUNIQUE de Apellidos y nombres
I30: VALLE FORTALEZA | J30: BOLOGNESI | K30: ANTONIO RAYMONDI | L30: 451 | M30: 2
K31: CAJACAY | L31: 048 ELVA BARBA TRINIDAD | M31: 4
L32: 1649 | M32: 5
L33: 616 | M33: 1
K34: COLQUIOC | L34: 028 | M34: 1
L35: 030 | M35: 1
L36: 1646 | M36: 2
L37: 357 | M37: 3
L38: LOS PALILLOS | M38: 2
J39: RECUAY | K39: PARARIN | L39: 2626 | M39: 2
L40: 394 | M40: 1
L41: 416 - Rinconada | M41: 3
I42: Suma total | M42: 27

Sheet Revisión cuaderno
A1: n° | B1: UGT | C1: Provincia | D1: Distrito | E1: Centro Poblado | F1: Institución educativa | G1: Nivel modular | H1: Cod modular | I1: Cod local | J1: Fecha de revisión | K1: Apellidos y nombres | L1: DNI | M1: Apellidos y nombre del niño/a | N1: Grado | O1: Aula/Sección | P1: Núcleo familiar | Q1: % Avance | R1: Comentarios | S1: Facilitador/a
B2: SAN MARCOS | C2: HUARI | D2: SAN MARCOS | E2: OPAYACO/OPAYACU | F2: 099 | G2: Inicial - Jardín | H2: 1551738 | I2: 631640 | J2: 45903 | K2: Rocia Mosquera Vega | M2: Leyva Mosquera Naim Owen | N2: Ini-3ero | O2: 3 años | P2: Leyva Mosquera Naim Owen/Ini-3ero/3 años | S2: Stephany Decheco Vera
B3: SAN MARCOS | C3: HUARI | D3: SAN MARCOS | E3: OPAYACO/OPAYACU | F3: 099 | G3: Inicial - Jardín | H3: 1551738 | I3: 631640 | J3: 45917 | K3: Rocia Mosquera Vega | M3: Leyva Mosquera Naim Owen | N3: Ini-3ero | O3: 3 años | P3: Leyva Mosquera Naim Owen/Ini-3ero/3 años | S3: Stephany Decheco Vera
B4: SAN MARCOS | C4: HUARI | D4: SAN MARCOS | E4: OPAYACO/OPAYACU | F4: 099 | G4: Inicial - Jardín | H4: 1551738 | I4: 631640 | J4: 45932 | K4: Rocia Mosquera Vega | M4: Leyva Mosquera Naim Owen | N4: Ini-3ero | O4: 3 años | P4: Leyva Mosquera Naim Owen/Ini-3ero/3 años | S4: Stephany Decheco Vera
B5: SAN MARCOS | C5: HUARI | D5: SAN MARCOS | E5: OPAYACO/OPAYACU | F5: 099 | G5: Inicial - Jardín | H5: 1551738 | I5: 631640 | J5: 45952 | K5: Rocia Mosquera Vega | M5: Leyva Mosquera Naim Owen | N5: Ini-3ero | O5: 3 años | P5: Leyva Mosquera Naim Owen/Ini-3ero/3 años | S5: Stephany Decheco Vera
B6: SAN MARCOS | C6: HUARI | D6: SAN MARCOS | E6: OPAYACO/OPAYACU | F6: 099 | G6: Inicial - Jardín | H6: 1551738 | I6: 631640 | J6: 45917 | K6: Andria Durán Flores | M6: Garay Durán Jahir Leandro | N6: Ini-3ero | O6: 3 años | P6: Garay Durán Jahir Leandro/Ini-3ero/3 años | S6: Stephany Decheco Vera
B7: SAN MARCOS | C7: HUARI | D7: SAN MARCOS | E7: OPAYACO/OPAYACU | F7: 099 | G7: Inicial - Jardín | H7: 1551738 | I7: 631640 | J7: 45932 | K7: Andria Durán Flores | M7: Garay Durán Jahir Leandro | N7: Ini-3ero | O7: 3 años | P7: Garay Durán Jahir Leandro/Ini-3ero/3 años | S7: Stephany Decheco Vera
B8: SAN MARCOS | C8: HUARI | D8: SAN MARCOS | E8: OPAYACO/OPAYACU | F8: 099 | G8: Inicial - Jardín | H8: 1551738 | I8: 631640 | J8: 45903 | K8: Edith Castro Veramendi | M8: Ortiz Castro Evelin Victoria Valentina | N8: Ini-3ero | O8: 3 años | P8: Ortiz Castro Evelin Victoria Valentina/Ini-3ero/3 años | S8: Stephany Decheco Vera
B9: MINA | C9: HUARI | D9: HUACHIS | E9: CAMBIO 90 | F9: LAS TRUCHAS | G9: Inicial No Escolarizado | H9: 0783226 | J9: 45916 | K9: Felix León Guisella | M9: Aquino Felix Samara Damaris | O9: única | P9: Aquino Felix Samara Damaris/única | Q9: 20 | S9: Jackelyn Juro Dueñas
B10: MINA | C10: HUARI | D10: HUACHIS | E10: CAMBIO 90 | F10: LAS TRUCHAS | G10: Inicial No Escolarizado | H10: 0783226 | J10: 45916 | K10: Gomez Alvarado Emma | L10: 72109011 | M10: Aquino Gomez Zohemy Skarlet | O10: única | P10: Aquino Gomez Zohemy Skarlet/única | Q10: 20 | S10: Jackelyn Juro Dueñas
B11: MINA | C11: HUARI | D11: HUACHIS | E11: CAMBIO 90 | F11: LAS TRUCHAS | G11: Inicial No Escolarizado | H11: 0783226 | J11: 45916 | K11: Alva Prada Isabela | M11: Garay Alva Adriel Dyam | O11: única | P11: Garay Alva Adriel Dyam/única | Q11: 20 | S11: Jackelyn Juro Dueñas
B12: MINA | C12: HUARI | D12: HUACHIS | E12: CAMBIO 90 | F12: LAS TRUCHAS | G12: Inicial No Escolarizado | H12: 0783226 | J12: 45916 | K12: Fernandez Flores Janet | L12: 10138468 | M12: Castro Fernandez Ghinna Mileth | O12: única | P12: Castro Fernandez Ghinna Mileth/única | Q12: 20 | S12: Jackelyn Juro Dueñas
B13: MINA | C13: HUARI | D13: HUACHIS | E13: CAMBIO 90 | F13: LAS TRUCHAS | G13: Inicial No Escolarizado | H13: 0783226 | J13: 45938 | K13: Felix León Guisella | M13: Aquino Felix Samara Damaris | O13: única | P13: Aquino Felix Samara Damaris/única | Q13: 50 | S13: Jackelyn Juro Dueñas
B14: MINA | C14: HUARI | D14: HUACHIS | E14: CAMBIO 90 | F14: LAS TRUCHAS | G14: Inicial No Escolarizado | H14: 0783226 | J14: 45938 | K14: Gomez Alvarado Emma | L14: 72109011 | M14: Aquino Gomez Zohemy Skarlet | O14: única | P14: Aquino Gomez Zohemy Skarlet/única | Q14: 50 | S14: Jackelyn Juro Dueñas
B15: MINA | C15: HUARI | D15: HUACHIS | E15: CAMBIO 90 | F15: LAS TRUCHAS | G15: Inicial No Escolarizado | H15: 0783226 | J15: 45938 | K15: Alva Prada Isabela | M15: Garay Alva Adriel Dyam | O15: única | P15: Garay Alva Adriel Dyam/única | Q15: 50 | S15: Jackelyn Juro Dueñas
B16: MINA | C16: HUARI | D16: HUACHIS | E16: CAMBIO 90 | F16: LAS TRUCHAS | G16: Inicial No Escolarizado | H16: 0783226 | J16: 45938 | K16: Fernandez Flores Janet | L16: 10138468 | M16: Castro Fernandez Ghinna Mileth | O16: única | P16: Castro Fernandez Ghinna Mileth/única | Q16: 50 | S16: Jackelyn Juro Dueñas
B17: MINA | C17: HUARI | D17: HUACHIS | E17: CAMBIO 90 | F17: LAS TRUCHAS | G17: Inicial No Escolarizado | H17: 0783226 | J17: 45961 | K17: Felix León Guisella | M17: Aquino Felix Samara Damaris | O17: única | P17: Aquino Felix Samara Damaris/única | Q17: 80 | S17: Jackelyn Juro Dueñas
B18: MINA | C18: HUARI | D18: HUACHIS | E18: CAMBIO 90 | F18: LAS TRUCHAS | G18: Inicial No Escolarizado | H18: 0783226 | J18: 45961 | K18: Gomez Alvarado Emma | L18: 72109011 | M18: Aquino Gomez Zohemy Skarlet | O18: única | P18: Aquino Gomez Zohemy Skarlet/única | Q18: 80 | S18: Jackelyn Juro Dueñas
B19: MINA | C19: HUARI | D19: HUACHIS | E19: CAMBIO 90 | F19: LAS TRUCHAS | G19: Inicial No Escolarizado | H19: 0783226 | J19: 45961 | K19: Alva Prada Isabela | M19: Garay Alva Adriel Dyam | O19: única | P19: Garay Alva Adriel Dyam/única | Q19: 80 | S19: Jackelyn Juro Dueñas
B20: MINA | C20: HUARI | D20: HUACHIS | E20: CAMBIO 90 | F20: LAS TRUCHAS | G20: Inicial No Escolarizado | H20: 0783226 | J20: 45961 | K20: Fernandez Flores Janet | L20: 10138468 | M20: Castro Fernandez Ghinna Mileth | O20: única | P20: Castro Fernandez Ghinna Mileth/única | Q20: 80 | S20: Jackelyn Juro Dueñas
B21: MINA | C21: HUARI | D21: HUACHIS | E21: CAMBIO 90 | F21: LAS TRUCHAS | G21: Inicial No Escolarizado | H21: 0783226 | J21: 45966 | K21: Felix León Guisella | M21: Aquino Felix Samara Damaris | O21: única | P21: Aquino Felix Samara Damaris/única | Q21: 100 | S21: Jackelyn Juro Dueñas
B22: MINA | C22: HUARI | D22: HUACHIS | E22: CAMBIO 90 | F22: LAS TRUCHAS | G22: Inicial No Escolarizado | H22: 0783226 | J22: 45966 | K22: Gomez Alvarado Emma | L22: 72109011 | M22: Aquino Gomez Zohemy Skarlet | O22: única | P22: Aquino Gomez Zohemy Skarlet/única | Q22: 100 | S22: Jackelyn Juro Dueñas
B23: MINA | C23: HUARI | D23: HUACHIS | E23: CAMBIO 90 | F23: LAS TRUCHAS | G23: Inicial No Escolarizado | H23: 0783226 | J23: 45966 | K23: Alva Prada Isabela | M23: Garay Alva Adriel Dyam | O23: única | P23: Garay Alva Adriel Dyam/única | Q23: 100 | S23: Jackelyn Juro Dueñas
B24: MINA | C24: HUARI | D24: HUACHIS | E24: CAMBIO 90 | F24: LAS TRUCHAS | G24: Inicial No Escolarizado | H24: 0783226 | J24: 45966 | K24: Fernandez Flores Janet | L24: 10138468 | M24: Castro Fernandez Ghinna Mileth | O24: única | P24: Castro Fernandez Ghinna Mileth/única | Q24: 100 | S24: Jackelyn Juro Dueñas
B25: MINA | C25: HUARI | D25: SAN PEDRO DE CHANA | E25: WISHLLAC | F25: 690 | G25: Inicial - Jardín | H25: 1675040 | I25: 759493 | J25: 45895 | K25: Evangelista Caqui Clerinda | L25: 71935349 | M25: Evangelista Caqui Clerinda | N25: Ini-5nto | O25: 5 años | P25: Castro Evangelista, Jafed | Q25: 20 | S25: Jackelyn Juro Dueñas
B26: MINA | C26: HUARI | D26: SAN PEDRO DE CHANA | E26: WISHLLAC | F26: 690 | G26: Inicial - Jardín | H26: 1675040 | I26: 759493 | J26: 45895 | K26: Evangelista Caqui Clerinda | L26: 71935349 | M26: Trujillo Guerra Marlene | N26: Ini-4rto | O26: 4 años | P26: Obregón Trujillo, Afret | Q26: 20 | S26: Jackelyn Juro Dueñas
B27: MINA | C27: HUARI | D27: SAN PEDRO DE CHANA | E27: WISHLLAC | F27: 690 | G27: Inicial - Jardín | H27: 1675040 | I27: 759493 | J27: 45895 | K27: Nuñez Silva Antonia | M27: Aquino Ramirez, Viviana | N27: Ini-4rto | O27: 4 años | P27: Aquino Ramirez, Viviana/Ini-4rto/4 años | Q27: 20 | S27: Jackelyn Juro Dueñas
B28: MINA | C28: HUARI | D28: SAN PEDRO DE CHANA | E28: WISHLLAC | F28: 690 | G28: Inicial - Jardín | H28: 1675040 | I28: 759493 | J28: 45910 | K28: Evangelista Caqui Clerinda | L28: 71935349 | M28: Evangelista Caqui Clerinda | N28: Ini-5nto | O28: 5 años | P28: Evangelista Caqui Clerinda/Ini-5nto/5 años | Q28: 50 | S28: Jackelyn Juro Dueñas
B29: MINA | C29: HUARI | D29: SAN PEDRO DE CHANA | E29: WISHLLAC | F29: 690 | G29: Inicial - Jardín | H29: 1675040 | I29: 759493 | J29: 45910 | K29: Evangelista Caqui Clerinda | L29: 71935349 | M29: Trujillo Guerra Marlene | N29: Ini-4rto | O29: 4 años | P29: Trujillo Guerra Marlene/Ini-4rto/4 años | Q29: 50 | S29: Jackelyn Juro Dueñas
B30: MINA | C30: HUARI | D30: SAN PEDRO DE CHANA | E30: WISHLLAC | F30: 690 | G30: Inicial - Jardín | H30: 1675040 | I30: 759493 | J30: 45938 | K30: Evangelista Caqui Clerinda | L30: 71935349 | M30: Evangelista Caqui Clerinda | N30: Ini-5nto | O30: 5 años | P30: Evangelista Caqui Clerinda/Ini-5nto/5 años | Q30: 80 | S30: Jackelyn Juro Dueñas
B31: MINA | C31: HUARI | D31: SAN PEDRO DE CHANA | E31: WISHLLAC | F31: 690 | G31: Inicial - Jardín | H31: 1675040 | I31: 759493 | J31: 45938 | K31: Evangelista Caqui Clerinda | L31: 71935349 | M31: Trujillo Guerra Marlene | N31: Ini-4rto | O31: 4 años | P31: Trujillo Guerra Marlene/Ini-4rto/4 años | Q31: 80 | S31: Jackelyn Juro Dueñas
B32: MINA | C32: HUARI | D32: SAN PEDRO DE CHANA | E32: WISHLLAC | F32: 690 | G32: Inicial - Jardín | H32: 1675040 | I32: 759493 | J32: 45959 | K32: Evangelista Caqui Clerinda | L32: 71935349 | M32: Evangelista Caqui Clerinda | N32: Ini-5nto | O32: 5 años | P32: Evangelista Caqui Clerinda/Ini-5nto/5 años | Q32: 100 | S32: Jackelyn Juro Dueñas
B33: MINA | C33: HUARI | D33: HUACHIS | E33: SAN CRISTOBAL DE TAMBO | F33: 688 | G33: Inicial - Jardín | H33: 1675024 | I33: 759474 | J33: 45937 | K33: Jemina Gadea Principe | L33: 76366959 | M33: Obregon Gadea Mia Isabella | O33: única | P33: Obregon Gadea Mia Isabella/única | Q33: 20 | S33: Jackelyn Juro Dueñas
B34: MINA | C34: HUARI | D34: HUACHIS | E34: SAN CRISTOBAL DE TAMBO | F34: 688 | G34: Inicial - Jardín | H34: 1675024 | I34: 759474 | J34: 45937 | K34: Ebilia Aquino Loarte | L34: 72118797 | M34: Melgarejo Aquino Liam Jayden | O34: única | P34: Melgarejo Aquino Liam Jayden/única | Q34: 20 | S34: Jackelyn Juro Dueñas
B35: MINA | C35: HUARI | D35: HUACHIS | E35: SAN CRISTOBAL DE TAMBO | F35: 688 | G35: Inicial - Jardín | H35: 1675024 | I35: 759474 | J35: 45937 | K35: Flor Rosales Carhuapoma | L35: 46514681 | M35: Aquino Rosales Danna Alisson | O35: única | P35: Aquino Rosales Danna Alisson/única | Q35: 20 | S35: Jackelyn Juro Dueñas
B36: MINA | C36: HUARI | D36: HUACHIS | E36: SAN CRISTOBAL DE TAMBO | F36: 688 | G36: Inicial - Jardín | H36: 1675024 | I36: 759474 | J36: 45937 | K36: Yolanda Suarez Huerta | L36: 47151224 | M36: Aquino Suarez Gael Loan | O36: única | P36: Aquino Suarez Gael Loan/única | Q36: 20 | S36: Jackelyn Juro Dueñas
B37: MINA | C37: HUARI | D37: HUACHIS | E37: SAN CRISTOBAL DE TAMBO | F37: 688 | G37: Inicial - Jardín | H37: 1675024 | I37: 759474 | J37: 45937 | K37: Rosaida Francisco Arquiñigo | L37: 71944773 | M37: Melgarejo Francisco Yamilet Kaida | O37: única | P37: Melgarejo Francisco Yamilet Kaida/única | Q37: 20 | S37: Jackelyn Juro Dueñas
B38: MINA | C38: HUARI | D38: HUACHIS | E38: SAN CRISTOBAL DE TAMBO | F38: 688 | G38: Inicial - Jardín | H38: 1675024 | I38: 759474 | J38: 45937 | K38: Ayde Aquino Loarte | L38: 73468926 | M38: Garay Aquino Eriksen Oliver | O38: única | P38: Garay Aquino Eriksen Oliver/única | Q38: 20 | S38: Jackelyn Juro Dueñas
B39: MINA | C39: HUARI | D39: HUACHIS | E39: SAN CRISTOBAL DE TAMBO | F39: 688 | G39: Inicial - Jardín | H39: 1675024 | I39: 759474 | J39: 45954 | K39: Jemina Gadea Principe | L39: 76366959 | M39: Obregon Gadea Mia Isabella | O39: única | P39: Obregon Gadea Mia Isabella/única | Q39: 50 | S39: Jackelyn Juro Dueñas
B40: MINA | C40: HUARI | D40: HUACHIS | E40: SAN CRISTOBAL DE TAMBO | F40: 688 | G40: Inicial - Jardín | H40: 1675024 | I40: 759474 | J40: 45954 | K40: Ebilia Aquino Loarte | L40: 72118797 | M40: Melgarejo Aquino Liam Jayden | O40: única | P40: Melgarejo Aquino Liam Jayden/única | Q40: 50 | S40: Jackelyn Juro Dueñas
...

Sheet Enc. Familias
B1: UGT | C1: Provincia | D1: Distrito | E1: Centro Poblado | F1: Institución educativa | G1: Nivel modular | H1: Cod modular | I1: Cod local | J1: Apellidos y nombres | K1: 🅱️ Normaliza nombres | L1: Relación con estudiante | M1: Edad | N1: Fecha de aplicación | O1: Corte de evaluación | P1: TRUE - Cuando me enojo con mis hijos/as, me doy cuenta de cómo me siento. | Q1: FALSE - A veces me pregunto si lo que hago como mamá o papá está bien para mis hijos/as. | R1: FALSE - Cuando estoy cansado/a o de mal humor, me cuesta tener paciencia con mis hijos/as.Cuando estoy cansado/a o de mal humor, me cuesta tener paciencia con mis hijos/as. | S1: TRUE - Cuando algo está difícil, trato de estar tranquilo/a antes de corregir a mis hijos/as. | T1: TRUE - Me doy cuenta cuando mi hijo/a está triste, aunque no lo diga. | U1: TRUE - En casa hablamos sobre cómo se siente cada uno. | V1: TRUE - En casa decimos lo que hacemos bien y también lo que podemos mejorar. | W1: TRUE - Cuando mi hijo/a se equivoca, le explico qué pasó y cómo puede hacerlo mejor. | X1: TRUE - Cuando hay decisiones importantes, las conversamos entre adultos en la casa. | Y1: TRUE - En mi casa, hombres y mujeres compartimos tareas como limpiar o cuidar a los niños/as. | Z1: FALSE - En mi comunidad, se espera que las niñas ayuden más en la casa que los niños. | AA1: FALSE - A veces pienso que los hombres no deben llorar ni mostrar tristeza. | AB1: TRUE - En mi familia, no siempre hablamos sobre cómo nos sentimos, pero lo estamos intentando. | AC1: FALSE - Cuando hay reunión en la escuela, casi siempre va la mamá, aunque también hay papás interesados. | AD1: 🅱️ Autoconciencia y Autorregulación Emocional | AE1: 🅱️ Toma de Decisiones Responsables | AF1: 🅱️ Habilidades Relacionales | AG1: ¿Qué te ayuda a ti, como mamá/papá, a estar bien? | AH1: Comentarios | AI1: Facilitador/a
B2: SAN MARCOS | C2: HUARI | D2: SAN MARCOS | E2: SANTA CRUZ DE MOSNA | F2: 435 | G2: Inicial - Jardín | H2: 1515246 | I2: 608381 | J2: PAOLA VICTORIA TOLENTITNO | K2: {=TRIM(UPPER(J2:J1076))} -> PAOLA VICTORIA TOLENTITNO | L2: Madre | M2: 36 | N2: 45834 | O2: Pre test (diagnóstico) | P2: 5 | Q2: 5 | R2: 5 | S2: 5 | T2: 3 | U2: 3 | V2: 3 | W2: 5 | X2: 3 | Y2: 3 | Z2: 3 | AA2: 5 | AB2: 3 | AC2: 3 | AD2: {=IF(J2:J1076="","", P2:P1076+(6-Q2:Q1076)+(6-R2:R1076)+S2:S1076+(6- AA2:AA1076))} -> 13 | AE2: {=IF(J2:J1076="","",W2:W1076+X2:X1076+Y2:Y1076+(5-Z2:Z1076)+(6-AC2:AC1076))} -> 16 | AF2: {=IF(J2:J1076="","",T2:T1076+U2:U1076+V2:V1076+AB2:AB1076)} -> 12 | AI2: Stephany Decheco Vera
B3: SAN MARCOS | C3: HUARI | D3: SAN MARCOS | E3: SANTA CRUZ DE MOSNA | F3: 435 | G3: Inicial - Jardín | H3: 1515246 | I3: 608381 | J3: SONIA RIMAC BALABARCA | K3: SONIA RIMAC BALABARCA | L3: Madre | M3: 26 | N3: 45834 | O3: Pre test (diagnóstico) | P3: 3 | Q3: 3 | R3: 4 | S3: 4 | T3: 3 | U3: 3 | V3: 3 | W3: 4 | X3: 5 | Y3: 5 | Z3: 3 | AA3: 3 | AB3: 3 | AC3: 5 | AD3: 15 | AE3: 17 | AF3: 12 | AG3: Tener tiempo de descanso y de juego con mis hijos | AI3: Stephany Decheco Vera
B4: SAN MARCOS | C4: HUARI | D4: SAN MARCOS | E4: SANTA CRUZ DE MOSNA | F4: 435 | G4: Inicial - Jardín | H4: 1515246 | I4: 608381 | J4: GLORIA CERPA POMA | K4: GLORIA CERPA POMA | L4: Madre | M4: 40 | N4: 45834 | O4: Pre test (diagnóstico) | P4: 2 | Q4: 2 | R4: 4 | S4: 4 | T4: 4 | U4: 4 | V4: 4 | W4: 4 | X4: 3 | Y4: 3 | Z4: 4 | AA4: 2 | AB4: 4 | AC4: 3 | AD4: 16 | AE4: 14 | AF4: 16 | AI4: Stephany Decheco Vera
B5: SAN MARCOS | C5: HUARI | D5: SAN MARCOS | E5: SANTA CRUZ DE MOSNA | F5: 435 | G5: Inicial - Jardín | H5: 1515246 | I5: 608381 | J5: YENI MINAYA MIRANDA | K5: YENI MINAYA MIRANDA | L5: Madre | M5: 34 | N5: 45834 | O5: Pre test (diagnóstico) | P5: 4 | Q5: 4 | R5: 4 | S5: 4 | T5: 4 | U5: 4 | V5: 4 | W5: 4 | X5: 4 | Y5: 4 | Z5: 4 | AA5: 4 | AB5: 4 | AC5: 4 | AD5: 14 | AE5: 15 | AF5: 16 | AG5: Tomar decisiones con mi familia e hijos | AI5: Stephany Decheco Vera
B6: SAN MARCOS | C6: HUARI | D6: SAN MARCOS | E6: SANTA CRUZ DE MOSNA | F6: 435 | G6: Inicial - Jardín | H6: 1515246 | I6: 608381 | L6: Madre | N6: 45834 | O6: Pre test (diagnóstico) | P6: 4 | Q6: 4 | R6: 4 | S6: 4 | T6: 4 | U6: 4 | V6: 4 | W6: 4 | X6: 3 | Y6: 3 | Z6: 4 | AA6: 4 | AB6: 4 | AC6: 3 | AG6: Estar atento de mis hijos | AI6: Stephany Decheco Vera
B7: SAN MARCOS | C7: HUARI | D7: SAN MARCOS | E7: SANTA CRUZ DE MOSNA | F7: 435 | G7: Inicial - Jardín | H7: 1515246 | I7: 608381 | J7: NARCIZA CUEVA TREJO | K7: NARCIZA CUEVA TREJO | L7: Madre | M7: 30 | N7: 45834 | O7: Pre test (diagnóstico) | P7: 3 | Q7: 3 | R7: 3 | S7: 3 | T7: 2 | U7: 4 | V7: 4 | W7: 3 | X7: 3 | Y7: 3 | Z7: 2 | AA7: 3 | AB7: 2 | AC7: 3 | AD7: 15 | AE7: 15 | AF7: 12 | AI7: Stephany Decheco Vera
B8: SAN MARCOS | C8: HUARI | D8: SAN MARCOS | E8: PUJUN | F8: 109 | G8: Inicial - Jardín | H8: 1551753 | I8: 631664 | J8: HILARIA ESPINOZA SALVADOR | K8: HILARIA ESPINOZA SALVADOR | L8: Madre | M8: 48 | N8: 45834 | O8: Pre test (diagnóstico) | P8: 2 | Q8: 2 | R8: 5 | S8: 5 | T8: 2 | U8: 1 | V8: 1 | W8: 5 | X8: 5 | Y8: 5 | Z8: 2 | AA8: 2 | AB8: 2 | AC8: 5 | AD8: 16 | AE8: 19 | AF8: 6 | AG8: Explicar a mi hijo sobre las normas | AI8: Stephany Decheco Vera
B9: SAN MARCOS | C9: HUARI | D9: SAN MARCOS | E9: SANTA CRUZ DE MOSNA | F9: 435 | G9: Inicial - Jardín | H9: 1515246 | I9: 608381 | J9: PAOLA GARCIA VERGARA | K9: PAOLA GARCIA VERGARA | L9: Madre | M9: 24 | N9: 45834 | O9: Pre test (diagnóstico) | P9: 4 | Q9: 4 | R9: 4 | S9: 4 | T9: 4 | U9: 4 | V9: 4 | W9: 4 | X9: 4 | Y9: 4 | Z9: 4 | AA9: 4 | AB9: 4 | AC9: 4 | AD9: 14 | AE9: 15 | AF9: 16 | AG9: Ver crecer feliz a mi hijo | AI9: Stephany Decheco Vera
B10: SAN MARCOS | C10: HUARI | D10: SAN MARCOS | E10: SANTA CRUZ DE MOSNA | F10: 435 | G10: Inicial - Jardín | H10: 1515246 | I10: 608381 | J10: KELY MERCEDES VARGAS SOLIS | K10: KELY MERCEDES VARGAS SOLIS | L10: Madre | M10: 26 | N10: 45834 | O10: Pre test (diagnóstico) | P10: 4 | Q10: 4 | R10: 4 | S10: 4 | T10: 4 | U10: 4 | V10: 4 | W10: 4 | X10: 4 | Y10: 4 | Z10: 4 | AA10: 4 | AB10: 4 | AC10: 4 | AD10: 14 | AE10: 15 | AF10: 16 | AG10: Ver que mi hijo esta creciendo bien integralmente | AI10: Stephany Decheco Vera
B11: SAN MARCOS | C11: HUARI | D11: SAN MARCOS | E11: SANTA CRUZ DE MOSNA | F11: 435 | G11: Inicial - Jardín | H11: 1515246 | I11: 608381 | J11: LETICIA FRIDA SOLORZANO SIFUENTES | K11: LETICIA FRIDA SOLORZANO SIFUENTES | L11: Madre | M11: 24 | N11: 45834 | O11: Pre test (diagnóstico) | P11: 4 | Q11: 4 | R11: 4 | S11: 4 | T11: 5 | U11: 4 | V11: 4 | W11: 4 | X11: 4 | Y11: 4 | Z11: 5 | AA11: 4 | AB11: 5 | AC11: 4 | AD11: 14 | AE11: 14 | AF11: 18 | AG11: Ver que mi hijo se encuentra bien integralmente | AI11: Stephany Decheco Vera
B12: SAN MARCOS | C12: HUARI | D12: SAN MARCOS | E12: SANTA CRUZ DE MOSNA | F12: 435 | G12: Inicial - Jardín | H12: 1515246 | I12: 608381 | J12: ELENA SIGUEÑAS ABARCA | K12: ELENA SIGUEÑAS ABARCA | L12: Madre | M12: 41 | N12: 45834 | O12: Pre test (diagnóstico) | P12: 4 | Q12: 4 | R12: 3 | S12: 3 | T12: 4 | U12: 4 | V12: 4 | W12: 3 | X12: 4 | Y12: 4 | Z12: 4 | AA12: 4 | AB12: 4 | AC12: 4 | AD12: 14 | AE12: 14 | AF12: 16 | AG12: Tomar acuerdos para el bien de mi hijo | AI12: Stephany Decheco Vera
B13: SAN MARCOS | C13: HUARI | D13: SAN MARCOS | E13: SANTA CRUZ DE MOSNA | F13: 435 | G13: Inicial - Jardín | H13: 1515246 | I13: 608381 | J13: ANAYELI ABARCA DAMIAN | K13: ANAYELI ABARCA DAMIAN | L13: Madre | M13: 23 | N13: 45834 | O13: Pre test (diagnóstico) | P13: 4 | Q13: 4 | R13: 5 | S13: 5 | T13: 5 | U13: 5 | V13: 5 | W13: 5 | X13: 5 | Y13: 5 | Z13: 5 | AA13: 4 | AB13: 5 | AC13: 5 | AD13: 14 | AE13: 16 | AF13: 20 | AG13: Compartir tiempo en familia | AI13: Stephany Decheco Vera
B14: SAN MARCOS | C14: HUARI | D14: SAN MARCOS | E14: SANTA CRUZ DE MOSNA | F14: 435 | G14: Inicial - Jardín | H14: 1515246 | I14: 608381 | J14: MARÍA PAUCAR DAMIAN | K14: MARÍA PAUCAR DAMIAN | L14: Madre | M14: 46 | N14: 45834 | O14: Pre test (diagnóstico) | P14: 4 | Q14: 4 | R14: 4 | S14: 4 | T14: 5 | U14: 4 | V14: 4 | W14: 4 | X14: 4 | Y14: 4 | Z14: 5 | AA14: 4 | AB14: 5 | AC14: 4 | AD14: 14 | AE14: 14 | AF14: 18 | AG14: Tener respeto y establecer acuerdos en familia | AI14: Stephany Decheco Vera
B15: SAN MARCOS | C15: HUARI | D15: SAN MARCOS | E15: SANTA CRUZ DE MOSNA | F15: 435 | G15: Inicial - Jardín | H15: 1515246 | I15: 608381 | J15: RODOLFO AMADO CADILLO | K15: RODOLFO AMADO CADILLO | L15: Padre | M15: 36 | N15: 45834 | O15: Pre test (diagnóstico) | P15: 4 | Q15: 4 | R15: 4 | S15: 4 | T15: 4 | U15: 4 | V15: 4 | W15: 4 | X15: 3 | Y15: 3 | Z15: 4 | AA15: 4 | AB15: 4 | AC15: 3 | AD15: 14 | AE15: 14 | AF15: 16 | AI15: Stephany Decheco Vera
B16: SAN MARCOS | C16: HUARI | D16: SAN MARCOS | E16: SANTA CRUZ DE MOSNA | F16: 435 | G16: Inicial - Jardín | H16: 1515246 | I16: 608381 | J16: AIDA FLOR RIVERA VALENZUELA | K16: AIDA FLOR RIVERA VALENZUELA | L16: Madre | M16: 24 | N16: 45834 | O16: Pre test (diagnóstico) | P16: 5 | Q16: 5 | R16: 4 | S16: 4 | T16: 4 | U16: 4 | V16: 4 | W16: 4 | X16: 4 | Y16: 4 | Z16: 4 | AA16: 5 | AB16: 4 | AC16: 4 | AD16: 13 | AE16: 15 | AF16: 16 | AG16: Ver que mi hijo se encuentra bien integralmente | AI16: Stephany Decheco Vera
B17: MINA | C17: HUARI | D17: SAN MARCOS | E17: CARHUAYOC | F17: 248 | G17: Inicial - Jardín | H17: 0509711 | I17: 025227 | J17: MAXIMO CUYA NARRO | K17: MAXIMO CUYA NARRO | L17: Padre | M17: 30 | N17: 45833 | O17: Pre test (diagnóstico) | P17: 4 | Q17: 4 | R17: 5 | S17: 5 | T17: 1 | U17: 4 | V17: 4 | W17: 5 | X17: 3 | Y17: 3 | Z17: 1 | AA17: 4 | AB17: 1 | AC17: 3 | AD17: 14 | AE17: 18 | AF17: 10 | AI17: Stephany Decheco Vera
B18: MINA | C18: HUARI | D18: SAN MARCOS | E18: CARHUAYOC | F18: 248 | G18: Inicial - Jardín | H18: 0509711 | I18: 025227 | J18: DELIA SALVADOR VALENCIA | K18: DELIA SALVADOR VALENCIA | L18: Madre | M18: 34 | N18: 45833 | O18: Pre test (diagnóstico) | P18: 3 | Q18: 3 | R18: 3 | S18: 3 | T18: 5 | U18: 4 | V18: 4 | W18: 3 | X18: 4 | Y18: 4 | Z18: 5 | AA18: 3 | AB18: 5 | AC18: 4 | AD18: 15 | AE18: 13 | AF18: 18 | AG18: Dialogar y salir en familia a despejar la mente, además de orar a Dios | AI18: Stephany Decheco Vera
B19: MINA | C19: HUARI | D19: SAN MARCOS | E19: CARHUAYOC | F19: 248 | G19: Inicial - Jardín | H19: 0509711 | I19: 025227 | J19: MARIBEL HARO SALAZAR | K19: MARIBEL HARO SALAZAR | L19: Madre | M19: 30 | N19: 45833 | O19: Pre test (diagnóstico) | P19: 4 | Q19: 4 | R19: 4 | S19: 4 | T19: 4 | U19: 4 | V19: 4 | W19: 4 | X19: 3 | Y19: 3 | Z19: 4 | AA19: 4 | AB19: 4 | AC19: 3 | AD19: 14 | AE19: 14 | AF19: 16 | AI19: Stephany Decheco Vera
B20: MINA | C20: HUARI | D20: SAN MARCOS | E20: CARHUAYOC | F20: 248 | G20: Inicial - Jardín | H20: 0509711 | I20: 025227 | J20: BRAYAN CARHUAPOMA TARAZONA | K20: BRAYAN CARHUAPOMA TARAZONA | L20: Padre | M20: 24 | N20: 45833 | O20: Pre test (diagnóstico) | P20: 3 | Q20: 3 | R20: 3 | S20: 3 | T20: 4 | U20: 4 | V20: 4 | W20: 3 | X20: 5 | Y20: 5 | Z20: 4 | AA20: 3 | AB20: 4 | AC20: 5 | AD20: 15 | AE20: 15 | AF20: 16 | AI20: Stephany Decheco Vera
B21: MINA | C21: HUARI | D21: SAN MARCOS | E21: CARHUAYOC | F21: 248 | G21: Inicial - Jardín | H21: 0509711 | I21: 025227 | J21: SARA LOPEZ VARGAS | K21: SARA LOPEZ VARGAS | L21: Madre | M21: 35 | N21: 45833 | O21: Pre test (diagnóstico) | P21: 3 | Q21: 3 | R21: 3 | S21: 3 | T21: 3 | U21: 3 | V21: 3 | W21: 3 | X21: 3 | Y21: 3 | Z21: 3 | AA21: 3 | AB21: 3 | AC21: 3 | AD21: 15 | AE21: 14 | AF21: 12 | AI21: Stephany Decheco Vera
B22: MINA | C22: HUARI | D22: SAN MARCOS | E22: CARHUAYOC | F22: 248 | G22: Inicial - Jardín | H22: 0509711 | I22: 025227 | J22: HILARIA SANTA ESPINOZA GUERRA | K22: HILARIA SANTA ESPINOZA GUERRA | L22: Madre | M22: 40 | N22: 45833 | O22: Pre test (diagnóstico) | P22: 3 | Q22: 3 | R22: 3 | S22: 3 | T22: 4 | U22: 4 | V22: 4 | W22: 3 | X22: 4 | Y22: 4 | Z22: 4 | AA22: 3 | AB22: 4 | AC22: 4 | AD22: 15 | AE22: 14 | AF22: 16 | AG22: Hablar con mis hijos para tomar buenas decisiones | AI22: Stephany Decheco Vera
B23: MINA | C23: HUARI | D23: SAN MARCOS | E23: CARHUAYOC | F23: 248 | G23: Inicial - Jardín | H23: 0509711 | I23: 025227 | J23: MARICRUZ ROMERO CASTRO | K23: MARICRUZ ROMERO CASTRO | L23: Madre | M23: 32 | N23: 45833 | O23: Pre test (diagnóstico) | P23: 5 | Q23: 5 | R23: 3 | S23: 3 | T23: 5 | U23: 5 | V23: 5 | W23: 3 | X23: 4 | Y23: 4 | Z23: 5 | AA23: 5 | AB23: 5 | AC23: 4 | AD23: 13 | AE23: 13 | AF23: 20 | AG23: Me ayuda que mis hijos vean que yo estoy bien | AI23: Stephany Decheco Vera
B24: MINA | C24: HUARI | D24: SAN MARCOS | E24: CARHUAYOC | F24: 248 | G24: Inicial - Jardín | H24: 0509711 | I24: 025227 | J24: NANCY GUERRA RAMIREZ | K24: NANCY GUERRA RAMIREZ | L24: Madre | M24: 35 | N24: 45833 | O24: Pre test (diagnóstico) | P24: 5 | Q24: 5 | R24: 5 | S24: 5 | T24: 4 | U24: 4 | V24: 4 | W24: 5 | X24: 5 | Y24: 5 | Z24: 4 | AA24: 5 | AB24: 4 | AC24: 5 | AD24: 13 | AE24: 17 | AF24: 16 | AG24: Me ayuda reflexionar y conversar con mis hijos | AI24: Stephany Decheco Vera
B25: MINA | C25: HUARI | D25: SAN MARCOS | E25: CARHUAYOC | F25: 248 | G25: Inicial - Jardín | H25: 0509711 | I25: 025227 | J25: ELENA EDITA DAVILA LOARTE | K25: ELENA EDITA DAVILA LOARTE | L25: Madre | M25: 35 | N25: 45833 | O25: Pre test (diagnóstico) | P25: 4 | Q25: 4 | R25: 4 | S25: 4 | T25: 4 | U25: 5 | V25: 5 | W25: 4 | X25: 5 | Y25: 5 | Z25: 4 | AA25: 4 | AB25: 4 | AC25: 5 | AD25: 14 | AE25: 16 | AF25: 18 | AI25: Stephany Decheco Vera
B26: MINA | C26: HUARI | D26: SAN MARCOS | E26: CARHUAYOC | F26: 248 | G26: Inicial - Jardín | H26: 0509711 | I26: 025227 | J26: LIDIA ZORRILA FONSECA | K26: LIDIA ZORRILA FONSECA | L26: Madre | M26: 36 | N26: 45833 | O26: Pre test (diagnóstico) | P26: 1 | Q26: 1 | R26: 4 | S26: 4 | T26: 4 | U26: 4 | V26: 4 | W26: 4 | X26: 4 | Y26: 4 | Z26: 4 | AA26: 1 | AB26: 4 | AC26: 4 | AD26: 17 | AE26: 15 | AF26: 16 | AG26: Me ayuda estar feliz y conversar con mis hijos | AI26: Stephany Decheco Vera
B27: MINA | C27: HUARI | D27: SAN MARCOS | E27: CARHUAYOC | F27: 248 | G27: Inicial - Jardín | H27: 0509711 | I27: 025227 | J27: JUAN DAVID QUISPE VARGAS | K27: JUAN DAVID QUISPE VARGAS | L27: Padre | M27: 32 | N27: 45833 | O27: Pre test (diagnóstico) | P27: 4 | Q27: 4 | R27: 4 | S27: 4 | T27: 4 | U27: 3 | V27: 3 | W27: 4 | X27: 4 | Y27: 4 | Z27: 4 | AA27: 4 | AB27: 4 | AC27: 4 | AD27: 14 | AE27: 15 | AF27: 14 | AG27: Saber que mis hijos estan sanos, tener un trabajo seguro y estar bien con mi familia | AI27: Stephany Decheco Vera
B28: MINA | C28: HUARI | D28: SAN MARCOS | E28: CARHUAYOC | F28: 248 | G28: Inicial - Jardín | H28: 0509711 | I28: 025227 | J28: SANDRA GOMEZ HILARIO | K28: SANDRA GOMEZ HILARIO | L28: Madre | M28: 34 | N28: 45833 | O28: Pre test (diagnóstico) | P28: 3 | Q28: 3 | R28: 3 | S28: 3 | T28: 5 | U28: 3 | V28: 3 | W28: 3 | X28: 3 | Y28: 3 | Z28: 5 | AA28: 3 | AB28: 5 | AC28: 3 | AD28: 15 | AE28: 12 | AF28: 16 | AG28: La unión de mi familia con buenos tratos | AI28: Stephany Decheco Vera
B29: MINA | C29: HUARI | D29: SAN MARCOS | E29: CARHUAYOC | F29: 248 | G29: Inicial - Jardín | H29: 0509711 | I29: 025227 | J29: OLINDA RAMOS GARGATE | K29: OLINDA RAMOS GARGATE | L29: Madre | M29: 28 | N29: 45833 | O29: Pre test (diagnóstico) | P29: 4 | Q29: 4 | R29: 4 | S29: 4 | T29: 4 | U29: 5 | V29: 5 | W29: 4 | X29: 5 | Y29: 5 | Z29: 4 | AA29: 4 | AB29: 4 | AC29: 5 | AD29: 14 | AE29: 16 | AF29: 18 | AG29: paciencia y hablarles con amor para que puedan entender | AI29: Stephany Decheco Vera
B30: MINA | C30: HUARI | D30: SAN MARCOS | E30: CARHUAYOC | F30: 248 | G30: Inicial - Jardín | H30: 0509711 | I30: 025227 | J30: TEODORA ARAUJO SOLIS | K30: TEODORA ARAUJO SOLIS | L30: Otro | M30: 53 | N30: 45833 | O30: Pre test (diagnóstico) | P30: 3 | Q30: 3 | R30: 4 | S30: 4 | T30: 4 | U30: 4 | V30: 4 | W30: 4 | X30: 4 | Y30: 4 | Z30: 4 | AA30: 3 | AB30: 4 | AC30: 4 | AD30: 15 | AE30: 15 | AF30: 16 | AG30: Jugar, explicar y preguntar cómo le esta yendo | AI30: Stephany Decheco Vera
B31: MINA | C31: HUARI | D31: SAN MARCOS | E31: CARHUAYOC | F31: 248 | G31: Inicial - Jardín | H31: 0509711 | I31: 025227 | J31: JAKELINE GUERRA ALFARO | K31: JAKELINE GUERRA ALFARO | L31: Madre | M31: 32 | N31: 45833 | O31: Pre test (diagnóstico) | P31: 5 | Q31: 5 | R31: 5 | S31: 5 | T31: 5 | U31: 5 | V31: 5 | W31: 5 | X31: 5 | Y31: 5 | AA31: 5 | AB31: 5 | AC31: 5 | AD31: 13 | AE31: 21 | AF31: 20 | AG31: Tratar de comprender cada situación | AI31: Stephany Decheco Vera
B32: MINA | C32: HUARI | D32: SAN MARCOS | E32: CARHUAYOC | F32: 248 | G32: Inicial - Jardín | H32: 0509711 | I32: 025227 | J32: YANIRA RAMOS GUERRA | K32: YANIRA RAMOS GUERRA | L32: Madre | M32: 39 | N32: 45833 | O32: Pre test (diagnóstico) | P32: 5 | Q32: 5 | R32: 4 | S32: 4 | T32: 5 | U32: 5 | V32: 5 | W32: 4 | X32: 5 | Y32: 5 | Z32: 5 | AA32: 5 | AB32: 5 | AC32: 5 | AD32: 13 | AE32: 15 | AF32: 20 | AI32: Stephany Decheco Vera
B33: MINA | C33: HUARI | D33: SAN MARCOS | E33: CARHUAYOC | F33: 248 | G33: Inicial - Jardín | H33: 0509711 | I33: 025227 | J33: ELISA GUERRA LAGUNA | K33: ELISA GUERRA LAGUNA | L33: Madre | M33: 30 | N33: 45833 | O33: Pre test (diagnóstico) | P33: 4 | Q33: 4 | R33: 5 | S33: 5 | T33: 5 | U33: 5 | V33: 5 | W33: 5 | X33: 4 | Y33: 4 | Z33: 5 | AA33: 4 | AB33: 5 | AC33: 4 | AD33: 14 | AE33: 15 | AF33: 20 | AG33: Estar bien con mi hijo, tratar de ayudar en sus emociones, la buena comunicación y confianza | AI33: Stephany Decheco Vera
B34: MINA | C34: HUARI | D34: SAN MARCOS | E34: CARHUAYOC | F34: 248 | G34: Inicial - Jardín | H34: 0509711 | I34: 025227 | J34: ROMELIA DIAZ ARQUINIZO | K34: ROMELIA DIAZ ARQUINIZO | L34: Madre | M34: 29 | N34: 45833 | O34: Pre test (diagnóstico) | P34: 4 | Q34: 4 | R34: 4 | S34: 4 | T34: 5 | U34: 4 | V34: 4 | W34: 4 | X34: 4 | Y34: 4 | Z34: 5 | AA34: 4 | AB34: 5 | AC34: 4 | AD34: 14 | AE34: 14 | AF34: 18 | AG34: Que mis hijos crezcan con valores y educados | AI34: Stephany Decheco Vera
B35: MINA | C35: HUARI | D35: SAN MARCOS | E35: CARHUAYOC | F35: 248 | G35: Inicial - Jardín | H35: 0509711 | I35: 025227 | J35: YISSELA TICLO GUERRA | K35: YISSELA TICLO GUERRA | L35: Madre | M35: 25 | N35: 45833 | O35: Pre test (diagnóstico) | P35: 4 | Q35: 4 | R35: 4 | S35: 4 | T35: 5 | U35: 3 | V35: 3 | W35: 4 | X35: 4 | Y35: 4 | Z35: 5 | AA35: 4 | AB35: 5 | AC35: 4 | AD35: 14 | AE35: 14 | AF35: 16 | AG35: Ser más responsable como mamá | AI35: Stephany Decheco Vera
B36: MINA | C36: HUARI | D36: SAN MARCOS | E36: CARHUAYOC | F36: 248 | G36: Inicial - Jardín | H36: 0509711 | I36: 025227 | J36: DIONY YLLARY MARQUEZ CHAVEZ | K36: DIONY YLLARY MARQUEZ CHAVEZ | L36: Otro | M36: 19 | N36: 45833 | O36: Pre test (diagnóstico) | P36: 4 | Q36: 4 | R36: 4 | S36: 4 | T36: 5 | U36: 3 | V36: 3 | W36: 4 | X36: 4 | Y36: 4 | Z36: 5 | AA36: 4 | AB36: 5 | AC36: 4 | AD36: 14 | AE36: 14 | AF36: 16 | AG36: Como hermana me gusta hablar con él, saber cómo esta | AI36: Stephany Decheco Vera
B37: MINA | C37: HUARI | D37: SAN MARCOS | E37: CARHUAYOC | F37: 248 | G37: Inicial - Jardín | H37: 0509711 | I37: 025227 | J37: VIOLETA AMADO SALAZAR | K37: VIOLETA AMADO SALAZAR | L37: Madre | M37: 37 | N37: 45833 | O37: Pre test (diagnóstico) | P37: 5 | Q37: 5 | R37: 4 | S37: 4 | T37: 5 | U37: 5 | V37: 5 | W37: 4 | X37: 5 | Y37: 5 | Z37: 5 | AA37: 5 | AB37: 5 | AC37: 5 | AD37: 13 | AE37: 15 | AF37: 20 | AG37: Conversar | AI37: Stephany Decheco Vera
B38: MINA | C38: HUARI | D38: SAN MARCOS | E38: CARHUAYOC | F38: 248 | G38: Inicial - Jardín | H38: 0509711 | I38: 025227 | J38: FELENA MALLQUI ARAUJO | K38: FELENA MALLQUI ARAUJO | L38: Madre | M38: 36 | N38: 45833 | O38: Pre test (diagnóstico) | P38: 4 | Q38: 4 | R38: 3 | S38: 3 | T38: 4 | U38: 4 | V38: 4 | W38: 3 | X38: 4 | Y38: 4 | Z38: 4 | AA38: 4 | AB38: 4 | AC38: 4 | AD38: 14 | AE38: 14 | AF38: 16 | AG38: Tratar de calmarme y corregirle | AI38: Stephany Decheco Vera
B39: MINA | C39: HUARI | D39: SAN MARCOS | E39: CARHUAYOC | F39: 248 | G39: Inicial - Jardín | H39: 0509711 | I39: 025227 | J39: ARAUJO GUERRA LUCINDA | K39: ARAUJO GUERRA LUCINDA | L39: Madre | M39: 26 | N39: 45833 | O39: Pre test (diagnóstico) | P39: 4 | Q39: 4 | R39: 4 | S39: 4 | T39: 4 | U39: 2 | V39: 2 | W39: 4 | X39: 2 | Y39: 2 | Z39: 4 | AA39: 4 | AB39: 4 | AC39: 2 | AD39: 14 | AE39: 13 | AF39: 12 | AG39: Tratar bien y jugar con mis hijos | AI39: Stephany Decheco Vera
B40: MINA | C40: HUARI | D40: SAN MARCOS | E40: CARHUAYOC | F40: 248 | G40: Inicial - Jardín | H40: 0509711 | I40: 025227 | J40: DEYSI SALAZAR VALVERDE | K40: DEYSI SALAZAR VALVERDE | L40: Madre | M40: 29 | N40: 45833 | O40: Pre test (diagnóstico) | P40: 5 | Q40: 5 | R40: 4 | S40: 4 | T40: 5 | U40: 5 | V40: 5 | W40: 4 | X40: 5 | Y40: 5 | Z40: 5 | AA40: 5 | AB40: 5 | AC40: 5 | AD40: 13 | AE40: 15 | AF40: 20 | AG40: Contar con el apoyo de mi familiar, y frente a cualquier problema resolverlo conversando con mi hija | AI40: Stephany Decheco Vera
...

Sheet 🅱️Enc. Familias
H2: {=SUM(IF(H4:H1578="",0,1))} -> 181 | I2: PADRES CON NOMBRE ESCRITO IGUAL
A3: ID | B3: ='Enc. Familias'!J1 -> Apellidos y nombres | C3: =COUNTA(C4:C1578) -> 1075 | J3: MISMO TEST? | K3: LISTAR COINCIDENCIAS | L3: PUEDEN SER IGUALES? (MISMO COLEGIO, EDAD, DIFERENTE TEST, COINCIDENCIAS EN NOMBRE) | M3: ID NUEVO BASED ON NAME | O3: PROCESA NOMBRE | R3: =CONCATENATE(S5:V9) -> 233 | AB3: =COUNTA(AB4:AB1578)/2&" POR EVALUAR" -> 28 POR EVALUAR | AK3: {='Enc. Familias'!P1:AG1} -> TRUE - Cuando me enojo con mis hijos/as, me doy cuenta de cómo me siento. | AL3: FALSE - A veces me pregunto si lo que hago como mamá o papá está bien para mis hijos/as. | AM3: FALSE - Cuando estoy cansado/a o de mal humor, me cuesta tener paciencia con mis hijos/as.Cuando estoy cansado/a o de mal humor, me cuesta tener paciencia con mis hijos/as. | AN3: TRUE - Cuando algo está difícil, trato de estar tranquilo/a antes de corregir a mis hijos/as. | AO3: TRUE - Me doy cuenta cuando mi hijo/a está triste, aunque no lo diga. | AP3: TRUE - En casa hablamos sobre cómo se siente cada uno. | AQ3: TRUE - En casa decimos lo que hacemos bien y también lo que podemos mejorar. | AR3: TRUE - Cuando mi hijo/a se equivoca, le explico qué pasó y cómo puede hacerlo mejor. | AS3: TRUE - Cuando hay decisiones importantes, las conversamos entre adultos en la casa. | AT3: TRUE - En mi casa, hombres y mujeres compartimos tareas como limpiar o cuidar a los niños/as. | AU3: FALSE - En mi comunidad, se espera que las niñas ayuden más en la casa que los niños. | AV3: FALSE - A veces pienso que los hombres no deben llorar ni mostrar tristeza. | AW3: TRUE - En mi familia, no siempre hablamos sobre cómo nos sentimos, pero lo estamos intentando. | AX3: FALSE - Cuando hay reunión en la escuela, casi siempre va la mamá, aunque también hay papás interesados. | AY3: 🅱️ Autoconciencia y Autorregulación Emocional | AZ3: 🅱️ Toma de Decisiones Responsables | BA3: 🅱️ Habilidades Relacionales | BB3: ¿Qué te ayuda a ti, como mamá/papá, a estar bien?
A4: 1 | B4: {=SORT(CHOOSECOLS('Enc. Familias'!G2:O1578,2,4,6,7,-1),2,false)} -> 0360305 | C4: ZUÑIGA FLORES ANDREA | D4: Madre | E4: 26 | F4: Pre test (diagnóstico) | K4: =IFERROR(__xludf.DUMMYFUNCTION("TRIM(JOIN("" "",UNIQUE(TOCOL(ARRAYFORMULA(IF( SPLIT(C4,"" "")=TOCOL(SPLIT(C3,"" "")),SPLIT(C4,"" "")&"" "",""""))))))"),"") | L4: =IF(((G4<>"")*(I4<>"")*(K4<>"")*( J4=FALSE)*( H4=""))>=1,"EVALUAR","")&IF(L5="EVALUAR","->WITH THIS","") | M4: =IF(H4="",A4,A3) -> 1 | S4: 1 | T4: 23 | U4: 2 | V4: 3 | AA4: =IFERROR(__xludf.DUMMYFUNCTION("FILTER(B4:F1578,L4:L1578<>"""")"),"1505023") -> 1505023 | AB4: =IFERROR(__xludf.DUMMYFUNCTION("""COMPUTED_VALUE"""),"YUDITH IRMA DAMIAN VALVERDE") -> YUDITH IRMA DAMIAN VALVERDE | AC4: =IFERROR(__xludf.DUMMYFUNCTION("""COMPUTED_VALUE"""),"Madre") -> Madre | AD4: =IFERROR(__xludf.DUMMYFUNCTION("""COMPUTED_VALUE"""),30.0) -> 30 | AE4: =IFERROR(__xludf.DUMMYFUNCTION("""COMPUTED_VALUE"""),"Pre test (diagnóstico)") -> Pre test (diagnóstico) | AK4: {=SORT(UNIQUE('Enc. Familias'!P2:P1578))} -> 1 | AL4: {=SORT(UNIQUE('Enc. Familias'!Q2:Q1578))} -> 1 | AM4: {=SORT(UNIQUE('Enc. Familias'!R2:R1578))} -> 1 | AN4: {=SORT(UNIQUE('Enc. Familias'!S2:S1578))} -> 1 | AO4: {=SORT(UNIQUE('Enc. Familias'!T2:T1578))} -> 1 | AP4: {=SORT(UNIQUE('Enc. Familias'!U2:U1578))} -> 1 | AQ4: {=SORT(UNIQUE('Enc. Familias'!V2:V1578))} -> 1 | AR4: {=SORT(UNIQUE('Enc. Familias'!W2:W1578))} -> 1 | ... AX4: {=SORT(UNIQUE('Enc. Familias'!AC2:AC1578))} -> 1 | AY4: {=SORT(UNIQUE('Enc. Familias'!AG2:AG1578))} -> A conversar con mi hija, preguntar como se siente
A5: =1+A4 -> 2 | B5: 1551555 | C5: ZUBIETA CERRATE, CAROLINA | D5: Madre | E5: 39 | F5: Post test (cierre) | G5: =IF(E4=E5,"misma edad","") | H5: =IF(C5=C4,"mismo nombre","") | I5: =IF(B4=B5,"mismo colegio","") | J5: =F5=F4 -> FALSE | K5: =IFERROR(__xludf.DUMMYFUNCTION("TRIM(JOIN("" "",UNIQUE(TOCOL(ARRAYFORMULA(IF( SPLIT(C5,"" "")=TOCOL(SPLIT(C4,"" "")),SPLIT(C5,"" "")&"" "",""""))))))"),"") | L5: =IF(((G5<>"")*(I5<>"")*(K5<>"")*( J5=FALSE)*( H5=""))>=1,"EVALUAR","")&IF(L6="EVALUAR","->WITH THIS","") | M5: =IF(H5="",A5,A4) -> 2 | R5: 12 | S5: {=IF(R5:R9=S4:V4,R5:R9,"")} | AA5: =IFERROR(__xludf.DUMMYFUNCTION("""COMPUTED_VALUE"""),"1505023") -> 1505023 | AB5: =IFERROR(__xludf.DUMMYFUNCTION("""COMPUTED_VALUE"""),"YUDITH DAMIAN VALVERDE") -> YUDITH DAMIAN VALVERDE | AC5: =IFERROR(__xludf.DUMMYFUNCTION("""COMPUTED_VALUE"""),"Madre") -> Madre | AD5: =IFERROR(__xludf.DUMMYFUNCTION("""COMPUTED_VALUE"""),30.0) -> 30 | AE5: =IFERROR(__xludf.DUMMYFUNCTION("""COMPUTED_VALUE"""),"Post test (cierre)") -> Post test (cierre) | AF5: =IFERROR(__xludf.DUMMYFUNCTION("TRIM(JOIN("" "",UNIQUE(TOCOL(ARRAYFORMULA(IF( SPLIT(AB5,"" "")=TOCOL(SPLIT(AB4,"" "")),SPLIT(AB5,"" "")&"" "",""""))))))"),"YUDITH DAMIAN VALVERDE") -> YUDITH DAMIAN VALVERDE | AK5: 2 | AL5: 2 | AM5: 2 | AN5: 2 | AO5: 2 | AP5: 2 | AQ5: 2 | AR5: 2 | AS5: 2 | AT5: 2 | AU5: 1 | AV5: 2 | AW5: 2 | AX5: 2 | AY5: -
A6: =1+A5 -> 3 | B6: 1597566 | C6: ZORRILLA BAZAN BEATRIZ | D6: Madre | E6: 39 | F6: Pre test (diagnóstico) | G6: =IF(E5=E6,"misma edad","") -> misma edad | H6: =IF(C6=C5,"mismo nombre","") | I6: =IF(B5=B6,"mismo colegio","") | J6: =F6=F5 -> FALSE | K6: =IFERROR(__xludf.DUMMYFUNCTION("TRIM(JOIN("" "",UNIQUE(TOCOL(ARRAYFORMULA(IF( SPLIT(C6,"" "")=TOCOL(SPLIT(C5,"" "")),SPLIT(C6,"" "")&"" "",""""))))))"),"") | L6: =IF(((G6<>"")*(I6<>"")*(K6<>"")*( J6=FALSE)*( H6=""))>=1,"EVALUAR","")&IF(L7="EVALUAR","->WITH THIS","") | M6: =IF(H6="",A6,A5) -> 3 | R6: 2 | U6: 2 | AA6: =IFERROR(__xludf.DUMMYFUNCTION("""COMPUTED_VALUE"""),"0509711") -> 0509711 | AB6: =IFERROR(__xludf.DUMMYFUNCTION("""COMPUTED_VALUE"""),"YANIRA RAMOS GUERRA") -> YANIRA RAMOS GUERRA | AC6: =IFERROR(__xludf.DUMMYFUNCTION("""COMPUTED_VALUE"""),"Madre") -> Madre | AD6: =IFERROR(__xludf.DUMMYFUNCTION("""COMPUTED_VALUE"""),39.0) -> 39 | AE6: =IFERROR(__xludf.DUMMYFUNCTION("""COMPUTED_VALUE"""),"Pre test (diagnóstico)") -> Pre test (diagnóstico) | AF6: =IFERROR(__xludf.DUMMYFUNCTION("TRIM(JOIN("" "",UNIQUE(TOCOL(ARRAYFORMULA(IF( SPLIT(AB6,"" "")=TOCOL(SPLIT(AB5,"" "")),SPLIT(AB6,"" "")&"" "",""""))))))"),"") | AK6: 3 | AL6: 3 | AM6: 3 | AN6: 3 | AO6: 3 | AP6: 3 | AQ6: 3 | AR6: 3 | AS6: 3 | AT6: 3 | AU6: 2 | AV6: 3 | AW6: 3 | AX6: 3 | AY6: A atender a mis hijos y poder ayudarlos y calmarlos cuando esten haciendo sus berrinches
A7: =1+A6 -> 4 | B7: 1597566 | C7: ZORRILLA BAZAN BEATRIZ | D7: Madre | E7: 39 | F7: Post test (cierre) | G7: =IF(E6=E7,"misma edad","") -> misma edad | H7: =IF(C7=C6,"mismo nombre","") -> mismo nombre | I7: =IF(B6=B7,"mismo colegio","") -> mismo colegio | J7: =F7=F6 -> FALSE | K7: =IFERROR(__xludf.DUMMYFUNCTION("TRIM(JOIN("" "",UNIQUE(TOCOL(ARRAYFORMULA(IF( SPLIT(C7,"" "")=TOCOL(SPLIT(C6,"" "")),SPLIT(C7,"" "")&"" "",""""))))))"),"ZORRILLA BAZAN BEATRIZ") -> ZORRILLA BAZAN BEATRIZ | L7: =IF(((G7<>"")*(I7<>"")*(K7<>"")*( J7=FALSE)*( H7=""))>=1,"EVALUAR","")&IF(L8="EVALUAR","->WITH THIS","") | M7: =IF(H7="",A7,A6) -> 3 | R7: 3 | V7: 3 | AA7: =IFERROR(__xludf.DUMMYFUNCTION("""COMPUTED_VALUE"""),"0509711") -> 0509711 | AB7: =IFERROR(__xludf.DUMMYFUNCTION("""COMPUTED_VALUE"""),"YANINA RAMOS GUERRA") -> YANINA RAMOS GUERRA | AC7: =IFERROR(__xludf.DUMMYFUNCTION("""COMPUTED_VALUE"""),"Madre") -> Madre | AD7: =IFERROR(__xludf.DUMMYFUNCTION("""COMPUTED_VALUE"""),39.0) -> 39 | AE7: =IFERROR(__xludf.DUMMYFUNCTION("""COMPUTED_VALUE"""),"Post test (cierre)") -> Post test (cierre) | AF7: =IFERROR(__xludf.DUMMYFUNCTION("TRIM(JOIN("" "",UNIQUE(TOCOL(ARRAYFORMULA(IF( SPLIT(AB7,"" "")=TOCOL(SPLIT(AB6,"" "")),SPLIT(AB7,"" "")&"" "",""""))))))"),"RAMOS GUERRA") -> RAMOS GUERRA | AK7: 4 | AL7: 4 | AM7: 4 | AN7: 4 | AO7: 4 | AP7: 4 | AQ7: 4 | AR7: 4 | AS7: 4 | AT7: 4 | AU7: 3 | AV7: 4 | AW7: 4 | AX7: 4 | AY7: A conversar con mi familia, jugar con mis hijas y salir a distraerme al campo.
A8: =1+A7 -> 5 | B8: 0415869 | C8: ZORAIDA PADILLA JARA | D8: Madre | E8: 32 | F8: Post test (cierre) | G8: =IF(E7=E8,"misma edad","") | H8: =IF(C8=C7,"mismo nombre","") | I8: =IF(B7=B8,"mismo colegio","") | J8: =F8=F7 -> TRUE | K8: =IFERROR(__xludf.DUMMYFUNCTION("TRIM(JOIN("" "",UNIQUE(TOCOL(ARRAYFORMULA(IF( SPLIT(C8,"" "")=TOCOL(SPLIT(C7,"" "")),SPLIT(C8,"" "")&"" "",""""))))))"),"") | L8: =IF(((G8<>"")*(I8<>"")*(K8<>"")*( J8=FALSE)*( H8=""))>=1,"EVALUAR","")&IF(L9="EVALUAR","->WITH THIS","") | M8: =IF(H8="",A8,A7) -> 5 | R8: 3 | V8: 3 | AA8: =IFERROR(__xludf.DUMMYFUNCTION("""COMPUTED_VALUE"""),"0509711") -> 0509711 | AB8: =IFERROR(__xludf.DUMMYFUNCTION("""COMPUTED_VALUE"""),"WILMER RIOS DIANES") -> WILMER RIOS DIANES | AC8: =IFERROR(__xludf.DUMMYFUNCTION("""COMPUTED_VALUE"""),"Padre") -> Padre | AD8: =IFERROR(__xludf.DUMMYFUNCTION("""COMPUTED_VALUE"""),38.0) -> 38 | AE8: =IFERROR(__xludf.DUMMYFUNCTION("""COMPUTED_VALUE"""),"Pre test (diagnóstico)") -> Pre test (diagnóstico) | AF8: =IFERROR(__xludf.DUMMYFUNCTION("TRIM(JOIN("" "",UNIQUE(TOCOL(ARRAYFORMULA(IF( SPLIT(AB8,"" "")=TOCOL(SPLIT(AB7,"" "")),SPLIT(AB8,"" "")&"" "",""""))))))"),"") | AK8: 5 | AL8: 5 | AM8: 5 | AN8: 5 | AO8: 5 | AP8: 5 | AQ8: 5 | AR8: 5 | AS8: 5 | AT8: 5 | AU8: 4 | AV8: 5 | AW8: 5 | AX8: 5 | AY8: A enseñarle que tengo paciencia y manejar las emociones.
A9: =1+A8 -> 6 | B9: 1505023 | C9: ZORAIDA JESUS TRINIDAD | D9: Madre | E9: 45 | F9: Pre test (diagnóstico) | G9: =IF(E8=E9,"misma edad","") | H9: =IF(C9=C8,"mismo nombre","") | I9: =IF(B8=B9,"mismo colegio","") | J9: =F9=F8 -> FALSE | K9: =IFERROR(__xludf.DUMMYFUNCTION("TRIM(JOIN("" "",UNIQUE(TOCOL(ARRAYFORMULA(IF( SPLIT(C9,"" "")=TOCOL(SPLIT(C8,"" "")),SPLIT(C9,"" "")&"" "",""""))))))"),"ZORAIDA") -> ZORAIDA | L9: =IF(((G9<>"")*(I9<>"")*(K9<>"")*( J9=FALSE)*( H9=""))>=1,"EVALUAR","")&IF(L10="EVALUAR","->WITH THIS","") | M9: =IF(H9="",A9,A8) -> 6 | R9: 434 | AA9: =IFERROR(__xludf.DUMMYFUNCTION("""COMPUTED_VALUE"""),"0509711") -> 0509711 | AB9: =IFERROR(__xludf.DUMMYFUNCTION("""COMPUTED_VALUE"""),"WILMER RIOS CHAVEZ | ANGELICA DIAZ LLIUYA") -> WILMER RIOS CHAVEZ | ANGELICA DIAZ LLIUYA | AC9: =IFERROR(__xludf.DUMMYFUNCTION("""COMPUTED_VALUE"""),"Padre") -> Padre | AD9: =IFERROR(__xludf.DUMMYFUNCTION("""COMPUTED_VALUE"""),38.0) -> 38 | AE9: =IFERROR(__xludf.DUMMYFUNCTION("""COMPUTED_VALUE"""),"Post test (cierre)") -> Post test (cierre) | AF9: =IFERROR(__xludf.DUMMYFUNCTION("TRIM(JOIN("" "",UNIQUE(TOCOL(ARRAYFORMULA(IF( SPLIT(AB9,"" "")=TOCOL(SPLIT(AB8,"" "")),SPLIT(AB9,"" "")&"" "",""""))))))"),"WILMER RIOS") -> WILMER RIOS | AR9: 8 | AU9: 5 | AY9: A estar bien con mi familia y tomar buenas decisiones.
A10: =1+A9 -> 7 | B10: 1505023 | C10: ZORAIDA JESUS TRINIDAD | D10: Madre | E10: 45 | F10: Post test (cierre) | G10: =IF(E9=E10,"misma edad","") -> misma edad | H10: =IF(C10=C9,"mismo nombre","") -> mismo nombre | I10: =IF(B9=B10,"mismo colegio","") -> mismo colegio | J10: =F10=F9 -> FALSE | K10: =IFERROR(__xludf.DUMMYFUNCTION("TRIM(JOIN("" "",UNIQUE(TOCOL(ARRAYFORMULA(IF( SPLIT(C10,"" "")=TOCOL(SPLIT(C9,"" "")),SPLIT(C10,"" "")&"" "",""""))))))"),"ZORAIDA JESUS TRINIDAD") -> ZORAIDA JESUS TRINIDAD | L10: =IF(((G10<>"")*(I10<>"")*(K10<>"")*( J10=FALSE)*( H10=""))>=1,"EVALUAR","")&IF(L11="EVALUAR","->WITH THIS","") | M10: =IF(H10="",A10,A9) -> 6 | AA10: =IFERROR(__xludf.DUMMYFUNCTION("""COMPUTED_VALUE"""),"0509711") -> 0509711 | AB10: =IFERROR(__xludf.DUMMYFUNCTION("""COMPUTED_VALUE"""),"WAGNER FERNANDEZ AIRA | FLOR HUERTA MALLQUI") -> WAGNER FERNANDEZ AIRA | FLOR HUERTA MALLQUI | AC10: =IFERROR(__xludf.DUMMYFUNCTION("""COMPUTED_VALUE"""),"Madre") -> Madre | AD10: =IFERROR(__xludf.DUMMYFUNCTION("""COMPUTED_VALUE"""),39.0) -> 39 | AE10: =IFERROR(__xludf.DUMMYFUNCTION("""COMPUTED_VALUE"""),"Post test (cierre)") -> Post test (cierre) | AF10: =IFERROR(__xludf.DUMMYFUNCTION("TRIM(JOIN("" "",UNIQUE(TOCOL(ARRAYFORMULA(IF( SPLIT(AB10,"" "")=TOCOL(SPLIT(AB9,"" "")),SPLIT(AB10,"" "")&"" "",""""))))))"),"|") -> | | AY10: A estar bien y a ser feliz.
A11: =1+A10 -> 8 | B11: 1675040 | C11: ZONIA MARGOT RIVERA CALDERÓN | D11: Madre | E11: 43 | F11: Pre test (diagnóstico) | G11: =IF(E10=E11,"misma edad","") | H11: =IF(C11=C10,"mismo nombre","") | I11: =IF(B10=B11,"mismo colegio","") | J11: =F11=F10 -> FALSE | K11: =IFERROR(__xludf.DUMMYFUNCTION("TRIM(JOIN("" "",UNIQUE(TOCOL(ARRAYFORMULA(IF( SPLIT(C11,"" "")=TOCOL(SPLIT(C10,"" "")),SPLIT(C11,"" "")&"" "",""""))))))"),"") | L11: =IF(((G11<>"")*(I11<>"")*(K11<>"")*( J11=FALSE)*( H11=""))>=1,"EVALUAR","")&IF(L12="EVALUAR","->WITH THIS","") | M11: =IF(H11="",A11,A10) -> 8 | O11: =IFERROR(__xludf.DUMMYFUNCTION("ARRAYFORMULA(IF( TOCOL(SPLIT(C21,"" ""))=(SPLIT(C20,"" "")),TOCOL(SPLIT(C21,"" ""))&"" "",""""))"),"YUPA ") -> YUPA | P11: =IFERROR(__xludf.DUMMYFUNCTION("""COMPUTED_VALUE"""),"") | Q11: =IFERROR(__xludf.DUMMYFUNCTION("""COMPUTED_VALUE"""),"") | AA11: =IFERROR(__xludf.DUMMYFUNCTION("""COMPUTED_VALUE"""),"0509711") -> 0509711 | AB11: =IFERROR(__xludf.DUMMYFUNCTION("""COMPUTED_VALUE"""),"WAGNER FERNANDEZ AIRA") -> WAGNER FERNANDEZ AIRA | AC11: =IFERROR(__xludf.DUMMYFUNCTION("""COMPUTED_VALUE"""),"Padre") -> Padre | AD11: =IFERROR(__xludf.DUMMYFUNCTION("""COMPUTED_VALUE"""),39.0) -> 39 | AE11: =IFERROR(__xludf.DUMMYFUNCTION("""COMPUTED_VALUE"""),"Pre test (diagnóstico)") -> Pre test (diagnóstico) | AF11: =IFERROR(__xludf.DUMMYFUNCTION("TRIM(JOIN("" "",UNIQUE(TOCOL(ARRAYFORMULA(IF( SPLIT(AB11,"" "")=TOCOL(SPLIT(AB10,"" "")),SPLIT(AB11,"" "")&"" "",""""))))))"),"WAGNER FERNANDEZ AIRA") -> WAGNER FERNANDEZ AIRA | AY11: A estar de acuerdo mutuamente ambos como pareja y que nuestros hijos crezcas respetuosos y sanitos y felices
A12: =1+A11 -> 9 | B12: 1675040 | C12: ZONIA MARGOT RIVERA CALDERÓN | D12: Madre | E12: 43 | F12: Post test (cierre) | G12: =IF(E11=E12,"misma edad","") -> misma edad | H12: =IF(C12=C11,"mismo nombre","") -> mismo nombre | I12: =IF(B11=B12,"mismo colegio","") -> mismo colegio | J12: =F12=F11 -> FALSE | K12: =IFERROR(__xludf.DUMMYFUNCTION("TRIM(JOIN("" "",UNIQUE(TOCOL(ARRAYFORMULA(IF( SPLIT(C12,"" "")=TOCOL(SPLIT(C11,"" "")),SPLIT(C12,"" "")&"" "",""""))))))"),"ZONIA MARGOT RIVERA CALDERÓN") -> ZONIA MARGOT RIVERA CALDERÓN | L12: =IF(((G12<>"")*(I12<>"")*(K12<>"")*( J12=FALSE)*( H12=""))>=1,"EVALUAR","")&IF(L13="EVALUAR","->WITH THIS","") | M12: =IF(H12="",A12,A11) -> 8 | O12: =IFERROR(__xludf.DUMMYFUNCTION("""COMPUTED_VALUE"""),"") | P12: =IFERROR(__xludf.DUMMYFUNCTION("""COMPUTED_VALUE"""),"PADILLA ") -> PADILLA | Q12: =IFERROR(__xludf.DUMMYFUNCTION("""COMPUTED_VALUE"""),"") | AA12: =IFERROR(__xludf.DUMMYFUNCTION("""COMPUTED_VALUE"""),"0509711") -> 0509711 | AB12: =IFERROR(__xludf.DUMMYFUNCTION("""COMPUTED_VALUE"""),"SUSA GARAY FERNANDEZ | FRANKLYN GARAY ESPINOZA") -> SUSA GARAY FERNANDEZ | FRANKLYN GARAY ESPINOZA | AC12: =IFERROR(__xludf.DUMMYFUNCTION("""COMPUTED_VALUE"""),"Padre") -> Padre | AD12: =IFERROR(__xludf.DUMMYFUNCTION("""COMPUTED_VALUE"""),32.0) -> 32 | AE12: =IFERROR(__xludf.DUMMYFUNCTION("""COMPUTED_VALUE"""),"Post test (cierre)") -> Post test (cierre) | AF12: =IFERROR(__xludf.DUMMYFUNCTION("TRIM(JOIN("" "",UNIQUE(TOCOL(ARRAYFORMULA(IF( SPLIT(AB12,"" "")=TOCOL(SPLIT(AB11,"" "")),SPLIT(AB12,"" "")&"" "",""""))))))"),"FERNANDEZ") -> FERNANDEZ | AY12: A estar en comunicación con todos y entendernos, la comprensión, el amor, la paz.
A13: =1+A12 -> 10 | B13: 1551738 | C13: ZOIDA HIDALGO POSTOR | D13: Madre | E13: 38 | F13: Pre test (diagnóstico) | G13: =IF(E12=E13,"misma edad","") | H13: =IF(C13=C12,"mismo nombre","") | I13: =IF(B12=B13,"mismo colegio","") | J13: =F13=F12 -> FALSE | K13: =IFERROR(__xludf.DUMMYFUNCTION("TRIM(JOIN("" "",UNIQUE(TOCOL(ARRAYFORMULA(IF( SPLIT(C13,"" "")=TOCOL(SPLIT(C12,"" "")),SPLIT(C13,"" "")&"" "",""""))))))"),"") | L13: =IF(((G13<>"")*(I13<>"")*(K13<>"")*( J13=FALSE)*( H13=""))>=1,"EVALUAR","")&IF(L14="EVALUAR","->WITH THIS","") | M13: =IF(H13="",A13,A12) -> 10 | O13: =IFERROR(__xludf.DUMMYFUNCTION("""COMPUTED_VALUE"""),"") | P13: =IFERROR(__xludf.DUMMYFUNCTION("""COMPUTED_VALUE"""),"") | Q13: =IFERROR(__xludf.DUMMYFUNCTION("""COMPUTED_VALUE"""),"ELVA ") -> ELVA | AA13: =IFERROR(__xludf.DUMMYFUNCTION("""COMPUTED_VALUE"""),"0509711") -> 0509711 | AB13: =IFERROR(__xludf.DUMMYFUNCTION("""COMPUTED_VALUE"""),"SUSA GARAY FERNANDEZ") -> SUSA GARAY FERNANDEZ | AC13: =IFERROR(__xludf.DUMMYFUNCTION("""COMPUTED_VALUE"""),"Madre") -> Madre | AD13: =IFERROR(__xludf.DUMMYFUNCTION("""COMPUTED_VALUE"""),32.0) -> 32 | AE13: =IFERROR(__xludf.DUMMYFUNCTION("""COMPUTED_VALUE"""),"Pre test (diagnóstico)") -> Pre test (diagnóstico) | AF13: =IFERROR(__xludf.DUMMYFUNCTION("TRIM(JOIN("" "",UNIQUE(TOCOL(ARRAYFORMULA(IF( SPLIT(AB13,"" "")=TOCOL(SPLIT(AB12,"" "")),SPLIT(AB13,"" "")&"" "",""""))))))"),"SUSA GARAY FERNANDEZ") -> SUSA GARAY FERNANDEZ | AY13: A mi como madre de ayuda a estar bien que mi hija se encuentre bien emocionalmente, fisicamente y psicológicamente
A14: =1+A13 -> 11 | B14: 0415869 | C14: ZAROLITA SOLANO ESPIRITU | D14: Madre | E14: 33 | F14: Pre test (diagnóstico) | G14: =IF(E13=E14,"misma edad","") | H14: =IF(C14=C13,"mismo nombre","") | I14: =IF(B13=B14,"mismo colegio","") | J14: =F14=F13 -> TRUE | K14: =IFERROR(__xludf.DUMMYFUNCTION("TRIM(JOIN("" "",UNIQUE(TOCOL(ARRAYFORMULA(IF( SPLIT(C14,"" "")=TOCOL(SPLIT(C13,"" "")),SPLIT(C14,"" "")&"" "",""""))))))"),"") | L14: =IF(((G14<>"")*(I14<>"")*(K14<>"")*( J14=FALSE)*( H14=""))>=1,"EVALUAR","")&IF(L15="EVALUAR","->WITH THIS","") | M14: =IF(H14="",A14,A13) -> 11 | AA14: =IFERROR(__xludf.DUMMYFUNCTION("""COMPUTED_VALUE"""),"1551738") -> 1551738 | AB14: =IFERROR(__xludf.DUMMYFUNCTION("""COMPUTED_VALUE"""),"SANTA ANAYA PEÑA") -> SANTA ANAYA PEÑA | AC14: =IFERROR(__xludf.DUMMYFUNCTION("""COMPUTED_VALUE"""),"Otro") -> Otro | AD14: =IFERROR(__xludf.DUMMYFUNCTION("""COMPUTED_VALUE"""),52.0) -> 52 | AE14: =IFERROR(__xludf.DUMMYFUNCTION("""COMPUTED_VALUE"""),"Post test (cierre)") -> Post test (cierre) | AF14: =IFERROR(__xludf.DUMMYFUNCTION("TRIM(JOIN("" "",UNIQUE(TOCOL(ARRAYFORMULA(IF( SPLIT(AB14,"" "")=TOCOL(SPLIT(AB13,"" "")),SPLIT(AB14,"" "")&"" "",""""))))))"),"") | AY14: A mi como mi mamá me ayudó a escuchar musica a acomodar mis cosas, ver un poco de tv y jugar con mi hija y mi pareja
A15: =1+A14 -> 12 | B15: 0750026 | C15: ZAMBRANO VERAMENDI, HUGO | D15: Padre | E15: 43 | F15: Post test (cierre) | G15: =IF(E14=E15,"misma edad","") | H15: =IF(C15=C14,"mismo nombre","") | I15: =IF(B14=B15,"mismo colegio","") | J15: =F15=F14 -> FALSE | K15: =IFERROR(__xludf.DUMMYFUNCTION("TRIM(JOIN("" "",UNIQUE(TOCOL(ARRAYFORMULA(IF( SPLIT(C15,"" "")=TOCOL(SPLIT(C14,"" "")),SPLIT(C15,"" "")&"" "",""""))))))"),"") | L15: =IF(((G15<>"")*(I15<>"")*(K15<>"")*( J15=FALSE)*( H15=""))>=1,"EVALUAR","")&IF(L16="EVALUAR","->WITH THIS","") | M15: =IF(H15="",A15,A14) -> 12 | AA15: =IFERROR(__xludf.DUMMYFUNCTION("""COMPUTED_VALUE"""),"1551738") -> 1551738 | AB15: =IFERROR(__xludf.DUMMYFUNCTION("""COMPUTED_VALUE"""),"SANTA ANAYA") -> SANTA ANAYA | AC15: =IFERROR(__xludf.DUMMYFUNCTION("""COMPUTED_VALUE"""),"Otro") -> Otro | AD15: =IFERROR(__xludf.DUMMYFUNCTION("""COMPUTED_VALUE"""),52.0) -> 52 | AE15: =IFERROR(__xludf.DUMMYFUNCTION("""COMPUTED_VALUE"""),"Pre test (diagnóstico)") -> Pre test (diagnóstico) | AF15: =IFERROR(__xludf.DUMMYFUNCTION("TRIM(JOIN("" "",UNIQUE(TOCOL(ARRAYFORMULA(IF( SPLIT(AB15,"" "")=TOCOL(SPLIT(AB14,"" "")),SPLIT(AB15,"" "")&"" "",""""))))))"),"SANTA ANAYA") -> SANTA ANAYA | AY15: A mi como papá me ayuda darle consejos y hacer chiste con mi hija, conversar siempre para que te entienda más o hacerle caso.
A16: =1+A15 -> 13 | B16: 0750026 | C16: ZAMBRANO SILVERIO, EDITH | D16: Madre | F16: Post test (cierre) | G16: =IF(E15=E16,"misma edad","") | H16: =IF(C16=C15,"mismo nombre","") | I16: =IF(B15=B16,"mismo colegio","") -> mismo colegio | J16: =F16=F15 -> TRUE | K16: =IFERROR(__xludf.DUMMYFUNCTION("TRIM(JOIN("" "",UNIQUE(TOCOL(ARRAYFORMULA(IF( SPLIT(C16,"" "")=TOCOL(SPLIT(C15,"" "")),SPLIT(C16,"" "")&"" "",""""))))))"),"ZAMBRANO") -> ZAMBRANO | L16: =IF(((G16<>"")*(I16<>"")*(K16<>"")*( J16=FALSE)*( H16=""))>=1,"EVALUAR","")&IF(L17="EVALUAR","->WITH THIS","") | M16: =IF(H16="",A16,A15) -> 13 | AA16: =IFERROR(__xludf.DUMMYFUNCTION("""COMPUTED_VALUE"""),"1551738") -> 1551738 | AB16: =IFERROR(__xludf.DUMMYFUNCTION("""COMPUTED_VALUE"""),"ROSA BLAS VILLANUEVA | FELICIANO ROJAS SANCHEZ") -> ROSA BLAS VILLANUEVA | FELICIANO ROJAS SANCHEZ | AC16: =IFERROR(__xludf.DUMMYFUNCTION("""COMPUTED_VALUE"""),"Padre") -> Padre | AD16: =IFERROR(__xludf.DUMMYFUNCTION("""COMPUTED_VALUE"""),30.0) -> 30 | AE16: =IFERROR(__xludf.DUMMYFUNCTION("""COMPUTED_VALUE"""),"Post test (cierre)") -> Post test (cierre) | AF16: =IFERROR(__xludf.DUMMYFUNCTION("TRIM(JOIN("" "",UNIQUE(TOCOL(ARRAYFORMULA(IF( SPLIT(AB16,"" "")=TOCOL(SPLIT(AB15,"" "")),SPLIT(AB16,"" "")&"" "",""""))))))"),"") | AY16: A mi lo que me ayuda a estar bien como mamá es im hijo que es mi mayor motivación y felciidad entre tristezas y llantos. El es mi mayor regalo que tengo.
A17: =1+A16 -> 14 | B17: 0750026 | C17: ZAMBRANO SALINAS, BONNY | D17: Madre | E17: 32 | F17: Post test (cierre) | G17: =IF(E16=E17,"misma edad","") | H17: =IF(C17=C16,"mismo nombre","") | I17: =IF(B16=B17,"mismo colegio","") -> mismo colegio | J17: =F17=F16 -> TRUE | K17: =IFERROR(__xludf.DUMMYFUNCTION("TRIM(JOIN("" "",UNIQUE(TOCOL(ARRAYFORMULA(IF( SPLIT(C17,"" "")=TOCOL(SPLIT(C16,"" "")),SPLIT(C17,"" "")&"" "",""""))))))"),"ZAMBRANO") -> ZAMBRANO | L17: =IF(((G17<>"")*(I17<>"")*(K17<>"")*( J17=FALSE)*( H17=""))>=1,"EVALUAR","")&IF(L18="EVALUAR","->WITH THIS","") | M17: =IF(H17="",A17,A16) -> 14 | AA17: =IFERROR(__xludf.DUMMYFUNCTION("""COMPUTED_VALUE"""),"1551738") -> 1551738 | AB17: =IFERROR(__xludf.DUMMYFUNCTION("""COMPUTED_VALUE"""),"ROSA BLAS VILLANUEVA") -> ROSA BLAS VILLANUEVA | AC17: =IFERROR(__xludf.DUMMYFUNCTION("""COMPUTED_VALUE"""),"Madre") -> Madre | AD17: =IFERROR(__xludf.DUMMYFUNCTION("""COMPUTED_VALUE"""),30.0) -> 30 | AE17: =IFERROR(__xludf.DUMMYFUNCTION("""COMPUTED_VALUE"""),"Pre test (diagnóstico)") -> Pre test (diagnóstico) | AF17: =IFERROR(__xludf.DUMMYFUNCTION("TRIM(JOIN("" "",UNIQUE(TOCOL(ARRAYFORMULA(IF( SPLIT(AB17,"" "")=TOCOL(SPLIT(AB16,"" "")),SPLIT(AB17,"" "")&"" "",""""))))))"),"ROSA BLAS VILLANUEVA") -> ROSA BLAS VILLANUEVA | AY17: A mí me ayuda a estar bien cuando mi hijo llega contento y feliz, contándome lo que ha aprendido en el colegio
A18: =1+A17 -> 15 | B18: 1551738 | C18: ZAIDA MELISSA CABRERA LOARTE | D18: Madre | E18: 18 | F18: Pre test (diagnóstico) | G18: =IF(E17=E18,"misma edad","") | H18: =IF(C18=C17,"mismo nombre","") | I18: =IF(B17=B18,"mismo colegio","") | J18: =F18=F17 -> FALSE | K18: =IFERROR(__xludf.DUMMYFUNCTION("TRIM(JOIN("" "",UNIQUE(TOCOL(ARRAYFORMULA(IF( SPLIT(C18,"" "")=TOCOL(SPLIT(C17,"" "")),SPLIT(C18,"" "")&"" "",""""))))))"),"") | L18: =IF(((G18<>"")*(I18<>"")*(K18<>"")*( J18=FALSE)*( H18=""))>=1,"EVALUAR","")&IF(L19="EVALUAR","->WITH THIS","") | M18: =IF(H18="",A18,A17) -> 15 | AA18: =IFERROR(__xludf.DUMMYFUNCTION("""COMPUTED_VALUE"""),"1515246") -> 1515246 | AB18: =IFERROR(__xludf.DUMMYFUNCTION("""COMPUTED_VALUE"""),"RODOLFO AMADO CADILLO | JANETH BAÑEZ NAVARRO") -> RODOLFO AMADO CADILLO | JANETH BAÑEZ NAVARRO | AC18: =IFERROR(__xludf.DUMMYFUNCTION("""COMPUTED_VALUE"""),"Padre") -> Padre | AD18: =IFERROR(__xludf.DUMMYFUNCTION("""COMPUTED_VALUE"""),36.0) -> 36 | AE18: =IFERROR(__xludf.DUMMYFUNCTION("""COMPUTED_VALUE"""),"Post test (cierre)") -> Post test (cierre) | AF18: =IFERROR(__xludf.DUMMYFUNCTION("TRIM(JOIN("" "",UNIQUE(TOCOL(ARRAYFORMULA(IF( SPLIT(AB18,"" "")=TOCOL(SPLIT(AB17,"" "")),SPLIT(AB18,"" "")&"" "",""""))))))"),"") | AY18: A mi me ayuda a estar bien los abrazos de mi hijo y cuando mi hijo es obediente y caballero con el resto.
A19: =1+A18 -> 16 | B19: 1558782 | C19: ZACARIAS PINEDA OCAÑA | D19: Padre | E19: 39 | F19: Pre test (diagnóstico) | G19: =IF(E18=E19,"misma edad","") | H19: =IF(C19=C18,"mismo nombre","") | I19: =IF(B18=B19,"mismo colegio","") | J19: =F19=F18 -> TRUE | K19: =IFERROR(__xludf.DUMMYFUNCTION("TRIM(JOIN("" "",UNIQUE(TOCOL(ARRAYFORMULA(IF( SPLIT(C19,"" "")=TOCOL(SPLIT(C18,"" "")),SPLIT(C19,"" "")&"" "",""""))))))"),"") | L19: =IF(((G19<>"")*(I19<>"")*(K19<>"")*( J19=FALSE)*( H19=""))>=1,"EVALUAR","")&IF(L20="EVALUAR","->WITH THIS","") | M19: =IF(H19="",A19,A18) -> 16 | O19: {=UNIQUE(TOCOL(O11:Q13))} -> YUPA | AA19: =IFERROR(__xludf.DUMMYFUNCTION("""COMPUTED_VALUE"""),"1515246") -> 1515246 | AB19: =IFERROR(__xludf.DUMMYFUNCTION("""COMPUTED_VALUE"""),"RODOLFO AMADO CADILLO") -> RODOLFO AMADO CADILLO | AC19: =IFERROR(__xludf.DUMMYFUNCTION("""COMPUTED_VALUE"""),"Padre") -> Padre | AD19: =IFERROR(__xludf.DUMMYFUNCTION("""COMPUTED_VALUE"""),36.0) -> 36 | AE19: =IFERROR(__xludf.DUMMYFUNCTION("""COMPUTED_VALUE"""),"Pre test (diagnóstico)") -> Pre test (diagnóstico) | AF19: =IFERROR(__xludf.DUMMYFUNCTION("TRIM(JOIN("" "",UNIQUE(TOCOL(ARRAYFORMULA(IF( SPLIT(AB19,"" "")=TOCOL(SPLIT(AB18,"" "")),SPLIT(AB19,"" "")&"" "",""""))))))"),"RODOLFO AMADO CADILLO") -> RODOLFO AMADO CADILLO | AY19: A mi me ayuda a estar bien que mis hijos esten bien
